Workbook
Name Levels: 'Do not use - Levels'!$A$5:$A$199
Name Sites: 'Do Not Use - Sites_Subsites'!$A$5:$A$279
Name Subsites: #REF!

Sheet Instruction Page
A1: Exhibition and League Games
A2: Use this spreadsheet for league and exhibition games
A3: Use one row per game.
A5: Do NOT enter games on this tab
A7: Sample Entry
A8: Date | B8: Time | C8: Location | D8: Gym | E8: Level | F8: Home | G8: Visitors
A9: mm-dd-yyyy | B9: hh:mm AM/PM | C9: School's Location | D9: Main Gym | E9: Game Level
A10: 44614 | B10: 0.72916667 | C10: st. Francis High School | D10: Main Gym | E10: Div 1/2 Junior Boys
A11: 44597 | B11: 0.33333333 | C11: Menno Simmons School | D11: Main Gym | E11: Junior High
B12: The format is important. AM or PM must be included. There must be a space betwen the time and AM/PM. Based on 12 hour clock. | C12: The place where the games are being played. But not the gym's name. Inlcude the full name (High School, Junior High, School, etc) | D12: The gym where the games are being played (Main Gym, North Gym, Court 1, Ross Gym, etc). | F12: This field is optional. | G12: This field is optional.
A13: It is important that location, gyms, and level match the choices available in the worksheet
A15: Enter Game Information on Next Worksheet
A19: Do NOT enter games on this tab
A21: Use the "League Games" tab

Sheet League Games
A1: Billing Information | D1: =IF(ISBLANK(C1), "<- Enter Billing Information", "") -> <- Enter Billing Information
A3: If you are including playoff games in the games list, remember to mark the games that are playoff games (click on the checkbox in the playoff column)
A5: Date (mm/dd/yyyy) | B5: Starting Time (AM/PM) | C5: Location | D5: Gym | E5: Level | F5: Home | G5: Visitors | H5: Playoff Game
H6: FALSE
H7: FALSE
H8: FALSE
H9: FALSE
H10: FALSE
H11: FALSE
H12: FALSE
H13: FALSE
H14: FALSE
H15: FALSE
H16: FALSE
H17: FALSE
... H250: FALSE

Sheet Do Not Use - Sites_Subsites
A2: Do not change anything on this worksheet | I2: Sites list starts here
I3: {=_xlfn.TAKE((IF('League Games'!C6 = "", "", TRANSPOSE(_xlfn._xlws.FILTER(B:B, ('League Games'!C6 = A:A))))), 1, 25)}
A4: Sites | I4: {=_xlfn.TAKE((IF('League Games'!C7 = "", "", TRANSPOSE(_xlfn._xlws.FILTER(B:B, ('League Games'!C7 = A:A))))), 1, 25)}
A5: A.E. Cross | B5: Main Gym | I5: {=_xlfn.TAKE((IF('League Games'!C8 = "", "", TRANSPOSE(_xlfn._xlws.FILTER(B:B, ('League Games'!C8 = A:A))))), 1, 25)}
A6: Airdrie 1 | B6: Airdrie 1 | I6: {=_xlfn.TAKE((IF('League Games'!C9 = "", "", TRANSPOSE(_xlfn._xlws.FILTER(B:B, ('League Games'!C9 = A:A))))), 1, 25)}
A7: Airdrie 1 | B7: Main Gym | I7: {=_xlfn.TAKE((IF('League Games'!C10 = "", "", TRANSPOSE(_xlfn._xlws.FILTER(B:B, ('League Games'!C10 = A:A))))), 1, 25)}
A8: Airdrie Christian Academy | B8: Main Gym | I8: {=_xlfn.TAKE((IF('League Games'!C11 = "", "", TRANSPOSE(_xlfn._xlws.FILTER(B:B, ('League Games'!C11 = A:A))))), 1, 25)}
A9: Airdrie Genesis Place | B9: Court 1 | I9: {=_xlfn.TAKE((IF('League Games'!C12 = "", "", TRANSPOSE(_xlfn._xlws.FILTER(B:B, ('League Games'!C12 = A:A))))), 1, 25)}
A10: Airdrie Genesis Place | B10: Court 2 | I10: {=_xlfn.TAKE((IF('League Games'!C13 = "", "", TRANSPOSE(_xlfn._xlws.FILTER(B:B, ('League Games'!C13 = A:A))))), 1, 25)}
A11: Airdrie Genesis Place | B11: Court 3 | I11: {=_xlfn.TAKE((IF('League Games'!C14 = "", "", TRANSPOSE(_xlfn._xlws.FILTER(B:B, ('League Games'!C14 = A:A))))), 1, 25)}
A12: Airdrie Genesis Place | B12: Court 4 | I12: {=_xlfn.TAKE((IF('League Games'!C15 = "", "", TRANSPOSE(_xlfn._xlws.FILTER(B:B, ('League Games'!C15 = A:A))))), 1, 25)}
A13: Airdrie Genesis Place | B13: Gym 1 | I13: {=_xlfn.TAKE((IF('League Games'!C16 = "", "", TRANSPOSE(_xlfn._xlws.FILTER(B:B, ('League Games'!C16 = A:A))))), 1, 25)}
A14: Airdrie Genesis Place | B14: Gym 2 | I14: {=_xlfn.TAKE((IF('League Games'!C17 = "", "", TRANSPOSE(_xlfn._xlws.FILTER(B:B, ('League Games'!C17 = A:A))))), 1, 25)}
A15: Alice Jamieson School (Stanley Jones) | B15: Main Gym | I15: {=_xlfn.TAKE((IF('League Games'!C18 = "", "", TRANSPOSE(_xlfn._xlws.FILTER(B:B, ('League Games'!C18 = A:A))))), 1, 25)}
A16: All Saints High School | B16: Aux. Gym | I16: {=_xlfn.TAKE((IF('League Games'!C19 = "", "", TRANSPOSE(_xlfn._xlws.FILTER(B:B, ('League Games'!C19 = A:A))))), 1, 25)}
... A103: Christ the King School - Calgary | B103: Main Gym | I103: {=_xlfn.TAKE((IF('League Games'!C106 = "", "", TRANSPOSE(_xlfn._xlws.FILTER(B:B, ('League Games'!C106 = A:A))))), 1, 25)}
A104: Church of Jesus Christ of Latter Day Saints | I104: {=_xlfn.TAKE((IF('League Games'!C107 = "", "", TRANSPOSE(_xlfn._xlws.FILTER(B:B, ('League Games'!C107 = A:A))))), 1, 25)}
A105: Clarence Sansom | B105: Main Gym | I105: {=_xlfn.TAKE((IF('League Games'!C108 = "", "", TRANSPOSE(_xlfn._xlws.FILTER(B:B, ('League Games'!C108 = A:A))))), 1, 25)}
A106: Clear Water Academy | B106: Court 1 | I106: {=_xlfn.TAKE((IF('League Games'!C109 = "", "", TRANSPOSE(_xlfn._xlws.FILTER(B:B, ('League Games'!C109 = A:A))))), 1, 25)}
A107: Clear Water Academy | B107: Court 2 | I107: {=_xlfn.TAKE((IF('League Games'!C110 = "", "", TRANSPOSE(_xlfn._xlws.FILTER(B:B, ('League Games'!C110 = A:A))))), 1, 25)}
A108: Clear Water Academy | B108: Main Gym | I108: {=_xlfn.TAKE((IF('League Games'!C111 = "", "", TRANSPOSE(_xlfn._xlws.FILTER(B:B, ('League Games'!C111 = A:A))))), 1, 25)}
A109: Cochrane High School | B109: Court 1 | I109: {=_xlfn.TAKE((IF('League Games'!C112 = "", "", TRANSPOSE(_xlfn._xlws.FILTER(B:B, ('League Games'!C112 = A:A))))), 1, 25)}
A110: Cochrane High School | B110: Court 2 | I110: {=_xlfn.TAKE((IF('League Games'!C113 = "", "", TRANSPOSE(_xlfn._xlws.FILTER(B:B, ('League Games'!C113 = A:A))))), 1, 25)}
A111: Cochrane High School | B111: Main Gym | I111: {=_xlfn.TAKE((IF('League Games'!C114 = "", "", TRANSPOSE(_xlfn._xlws.FILTER(B:B, ('League Games'!C114 = A:A))))), 1, 25)}
A112: Colonel Irvine School | B112: Main Gym | I112: {=_xlfn.TAKE((IF('League Games'!C115 = "", "", TRANSPOSE(_xlfn._xlws.FILTER(B:B, ('League Games'!C115 = A:A))))), 1, 25)}
A113: Colonel Macleod School | B113: Main Gym | I113: {=_xlfn.TAKE((IF('League Games'!C116 = "", "", TRANSPOSE(_xlfn._xlws.FILTER(B:B, ('League Games'!C116 = A:A))))), 1, 25)}
A114: Cremona School | B114: Main Gym | I114: {=_xlfn.TAKE((IF('League Games'!C117 = "", "", TRANSPOSE(_xlfn._xlws.FILTER(B:B, ('League Games'!C117 = A:A))))), 1, 25)}
A115: Crescent Heights High School | B115: Aux. Gym | I115: {=_xlfn.TAKE((IF('League Games'!C118 = "", "", TRANSPOSE(_xlfn._xlws.FILTER(B:B, ('League Games'!C118 = A:A))))), 1, 25)}
A116: Crescent Heights High School | B116: Court 1 | I116: {=_xlfn.TAKE((IF('League Games'!C119 = "", "", TRANSPOSE(_xlfn._xlws.FILTER(B:B, ('League Games'!C119 = A:A))))), 1, 25)}
... A140: East Lake School | B140: East Lake School | I140: {=_xlfn.TAKE((IF('League Games'!C143 = "", "", TRANSPOSE(_xlfn._xlws.FILTER(B:B, ('League Games'!C143 = A:A))))), 1, 25)}
A141: Ecole Beausoliel | B141: Main Gym
A142: Ecole de La Rose Sauvage | B142: Main Gym | I142: {=_xlfn.TAKE((IF('League Games'!C144 = "", "", TRANSPOSE(_xlfn._xlws.FILTER(B:B, ('League Games'!C144 = A:A))))), 1, 25)}
A143: Ecole des Hautes-Plaines | B143: Aux Gym | I143: {=_xlfn.TAKE((IF('League Games'!C145 = "", "", TRANSPOSE(_xlfn._xlws.FILTER(B:B, ('League Games'!C145 = A:A))))), 1, 25)}
A144: Ecole des Hautes-Plaines | B144: Main Gym | I144: {=_xlfn.TAKE((IF('League Games'!C146 = "", "", TRANSPOSE(_xlfn._xlws.FILTER(B:B, ('League Games'!C146 = A:A))))), 1, 25)}
A145: Ecole des Hautes-Plaines | B145: Main Gym | I145: {=_xlfn.TAKE((IF('League Games'!C147 = "", "", TRANSPOSE(_xlfn._xlws.FILTER(B:B, ('League Games'!C147 = A:A))))), 1, 25)}
A146: Ecole Silverado | B146: Main Gym
A147: Edge School for Athletes | B147: Court 1 | I147: {=_xlfn.TAKE((IF('League Games'!C148 = "", "", TRANSPOSE(_xlfn._xlws.FILTER(B:B, ('League Games'!C148 = A:A))))), 1, 25)}
A148: Edge School for Athletes | B148: Court 2 | I148: {=_xlfn.TAKE((IF('League Games'!C149 = "", "", TRANSPOSE(_xlfn._xlws.FILTER(B:B, ('League Games'!C149 = A:A))))), 1, 25)}
A149: Edge School for Athletes | B149: Main Gym | I149: {=_xlfn.TAKE((IF('League Games'!C150 = "", "", TRANSPOSE(_xlfn._xlws.FILTER(B:B, ('League Games'!C150 = A:A))))), 1, 25)}
A150: Elboya School | B150: Main Gym | I150: {=_xlfn.TAKE((IF('League Games'!C151 = "", "", TRANSPOSE(_xlfn._xlws.FILTER(B:B, ('League Games'!C151 = A:A))))), 1, 25)}
...

Sheet Do not use - Levels
A2: Do not change anything on this worksheet
A4: Levels
A5: Adult 3x3
A6: Calgary Corporate Challenge
A7: Canadian Junior Basketball League
A8: CESAA Jr Boys
A9: CESAA Jr Girls
A10: CESAA Sr Boys
A11: CESAA Sr Boys
A12: CESAA Sr Girls
A13: CHSSL Sr Boys
A14: CHSSL Sr Girls
... A28: Edge School Sr Girls
A29: Foothills Jr Boys | F29: -
A30: Foothills Jr Girls
A31: Foothills Sr Boys
A32: Foothills Sr Girls
A33: ISAA Jr Girls
A34: ISAA Jr Boys
A35: ISAA Sr Boys
A36: ISAA Sr Girls
A37: Junior High - Sr Boys
A38: Junior High - Sr Girls
A39: Junior High - Jr Boys
A40: Junior High - Jr Girls
A41: Junior B Boys
... A132: Womens Masters
